Workbook

Sheet Anafi
A2: ANALYSE FINANCIERE - UNIWAX
A4: Compte de résultat | G4: Compte de résultat en %
A5: (Clôture des comptes le 31 décembre de chaque exercice) | G5: =A5 -> (Clôture des comptes le 31 décembre de chaque exercice)
A7: En million de FCFA | B7: 2015 | C7: =1+B7 -> 2016 | D7: 2017 | E7: 2018 | G7: En % de la production | H7: =B7 -> 2015 | I7: =C7 -> 2016 | J7: =D7 -> 2017 | K7: =E7 -> 2018
A8: Chiffre d'affaires | B8: 39395 | C8: 37164 | D8: 37667 | E8: 38977 | G8: =A8 -> Chiffre d'affaires | H8: =B8/B$15 -> 0.98979925 | I8: =C8/C$15 -> 0.98213531 | J8: =D8/D$15 -> 1.0147633 | K8: =E8/E$15 -> 1.000154
A9: en millions de yards | B9: 25.621 | C9: =D9/1.002 -> 23.922156 | D9: 23.97 | E9: 25 | G9: =A9 -> en millions de yards | H9: =B9/B$8 -> 0.00065036172 | I9: =C9/C$8 -> 0.00064369163 | J9: =D9/D$8 -> 0.00063636605 | K9: =E9/E$8 -> 0.0006414039
A10: Croissance nominale | C10: =C8/B8-1 -> -0.056631552 | D10: =D8/C8-1 -> 0.013534603 | E10: =E8/D8-1 -> 0.034778453
A11: Croissance en volume | B11: =B9/24-1 -> 0.067541667 | C11: =C9/B9-1 -> -0.066306714 | D11: =D9/C9-1 -> 0.002 | E11: =E9/D9-1 -> 0.04297038 | G11: =A11 -> Croissance en volume | H11: =B11/B$8 -> 1.7144731e-06 | I11: =C11/C$8 -> -1.7841652e-06 | J11: =D11/D$8 -> 5.3096875e-08 | K11: =E11/E$8 -> 1.1024548e-06
A12: Croissance en prix | C12: =(1+C10)/(1+C11)-1 -> 0.010362248 | D12: =(1+D10)/(1+D11)-1 -> 0.01151158 | E12: =(1+E10)/(1+E11)-1 -> -0.007854419 | G12: =A12 -> Croissance en prix | H12: =B12/B$8 -> 0 | I12: =C12/C$8 -> 2.7882489e-07 | J12: =D12/D$8 -> 3.0561447e-07 | K12: =E12/E$8 -> -2.015142e-07
A13: + Production immobilisée | G13: =A13 -> + Production immobilisée | H13: =B13/B$15 -> 0 | I13: =C13/C$15 -> 0 | J13: =D13/D$15 -> 0 | K13: =E13/E$15 -> 0
A14: + Production stockée | B14: 406 | C14: 676 | D14: -548 | E14: -6 | G14: =A14 -> + Production stockée | H14: =B14/B$15 -> 0.010200749 | I14: =C14/C$15 -> 0.017864693 | J14: =D14/D$15 -> -0.014763329 | K14: =E14/E$15 -> -0.00015396064
A15: = Production | B15: =B8+B14+B13 -> 39801 | C15: =C8+C14+C13 -> 37840 | D15: =D8+D14+D13 -> 37119 | E15: =E8+E14+E13 -> 38971 | G15: =A15 -> = Production | H15: =B15/B$15 -> 1 | I15: =C15/C$15 -> 1 | J15: =D15/D$15 -> 1 | K15: =E15/E$15 -> 1
A16: - Achats consommés | B16: =SUM(B17:B19) -> 23406 | C16: =SUM(C17:C19) -> 21668 | D16: =SUM(D17:D19) -> 22215 | E16: =SUM(E17:E19) -> 23847 | G16: =A16 -> - Achats consommés | H16: =B16/B$15 -> 0.58807568 | I16: =C16/C$15 -> 0.57262156 | J16: =D16/D$15 -> 0.59848056 | K16: =E16/E$15 -> 0.61191655
A17: dont consommation matières premieres | B17: =18821-221 -> 18600 | C17: =17651-148 -> 17503 | D17: =18353+250 -> 18603 | E17: =20609+42 -> 20651 | G17: =A17 -> dont consommation matières premieres
A18: dont énergie | B18: 3161 | C18: =4115-126+176 -> 4165 | D18: =3988-582+206 -> 3612 | E18: =3508-484+172 -> 3196 | G18: =A18 -> dont énergie
A19: dont autres | B19: =4878-245+173-B18 -> 1645 | G19: =A19 -> dont autres
A20: = Marge brute | B20: =B15-B16 -> 16395 | C20: =C15-C16 -> 16172 | D20: =D15-D16 -> 14904 | E20: =E15-E16 -> 15124 | G20: =A20 -> = Marge brute | H20: =B20/B$15 -> 0.41192432 | I20: =C20/C$15 -> 0.42737844 | J20: =D20/D$15 -> 0.40151944 | K20: =E20/E$15 -> 0.38808345
A21: - Charges externes (communication et autres) | B21: 3110 | C21: 3088 | D21: 2952 | E21: 3233 | G21: =A21 -> - Charges externes (communication et autres) | H21: =B21/B$15 -> 0.07813874 | I21: =C21/C$15 -> 0.081606765 | J21: =D21/D$15 -> 0.079528005 | K21: =E21/E$15 -> 0.082959123
A22: = Valeur ajoutée | B22: =B20-B21 -> 13285 | C22: =C20-C21 -> 13084 | D22: =D20-D21 -> 11952 | E22: =E20-E21 -> 11891 | G22: =A22 -> = Valeur ajoutée | H22: =B22/B$15 -> 0.33378558 | I22: =C22/C$15 -> 0.34577167 | J22: =D22/D$15 -> 0.32199143 | K22: =E22/E$15 -> 0.30512432
A23: - Charges de personnel | B23: 4795 | C23: 5063 | D23: 5187 | E23: 5250 | G23: =A23 -> - Charges de personnel | H23: =B23/B$15 -> 0.12047436 | I23: =C23/C$15 -> 0.13380021 | J23: =D23/D$15 -> 0.13973976 | K23: =E23/E$15 -> 0.13471556
A24: - Impôts et taxes | B24: 583 | C24: 640 | D24: 592 | E24: 512 | G24: =A24 -> - Impôts et taxes | H24: =B24/B$15 -> 0.014647873 | I24: =C24/C$15 -> 0.016913319 | J24: =D24/D$15 -> 0.015948706 | K24: =E24/E$15 -> 0.013137974
A25: +/- Autres produits/ charges | B25: =681-250 -> 431 | C25: =1723-1617 -> 106 | D25: =1947-1515 -> 432 | E25: =378-63 -> 315 | G25: =A25 -> +/- Autres produits/ charges | H25: =B25/B$15 -> 0.010828874 | I25: =C25/C$15 -> 0.0028012685 | J25: =D25/D$15 -> 0.011638245 | K25: =E25/E$15 -> 0.0080829335
A26: = Excédent brut d'exploitation | B26: =B22-B23-B24+B25 -> 8338 | C26: =C22-C23-C24+C25 -> 7487 | D26: =D22-D23-D24+D25 -> 6605 | E26: =E22-E23-E24+E25 -> 6444 | G26: =A26 -> = Excédent brut d'exploitation | H26: =B26/B$15 -> 0.20949222 | I26: =C26/C$15 -> 0.19785941 | J26: =D26/D$15 -> 0.17794122 | K26: =E26/E$15 -> 0.16535372
A27: - Dotations aux amortissements | B27: 1068 | C27: 1061 | D27: 1168 | E27: =2261-1328 -> 933 | G27: =A27 -> - Dotations aux amortissements | H27: =B27/B$15 -> 0.026833497 | I27: =C27/C$15 -> 0.028039112 | J27: =D27/D$15 -> 0.031466365 | K27: =E27/E$15 -> 0.023940879
A28: = Résultat d'exploitation | B28: =B26-B27 -> 7270 | C28: =C26-C27 -> 6426 | D28: =D26-D27 -> 5437 | E28: =E26-E27 -> 5511 | G28: =A28 -> = Résultat d'exploitation | H28: =B28/B$15 -> 0.18265873 | I28: =C28/C$15 -> 0.1698203 | J28: =D28/D$15 -> 0.14647485 | K28: =E28/E$15 -> 0.14141285
A29: - Coût de l'endettement net | B29: =591-77 -> 514 | C29: =224 -> 224 | D29: 38 | E29: =99-67 -> 32 | G29: =A29 -> - Coût de l'endettement net | H29: =B29/B$15 -> 0.012914248 | I29: =C29/C$15 -> 0.0059196617 | J29: =D29/D$15 -> 0.0010237345 | K29: =E29/E$15 -> 0.0008211234
A30: + Autres éléments financiers | B30: =-157-570 -> -727 | C30: =45-190+3 -> -142 | D30: =162-115 -> 47 | G30: =A30 -> + Autres éléments financiers | H30: =B30/B$15 -> -0.018265873 | I30: =C30/C$15 -> -0.0037526427 | J30: =D30/D$15 -> 0.0012661979 | K30: =E30/E$15 -> 0
A31: + Eléments non récurrents | B31: 6 | C31: =6-15 -> -9 | D31: 6 | E31: 1 | G31: =A31 -> + Eléments non récurrents | H31: =B31/B$15 -> 0.00015074998 | I31: =C31/C$15 -> -0.00023784355 | J31: =D31/D$15 -> 0.00016164229 | K31: =E31/E$15 -> 2.5660106e-05
A32: = Résultat avant impôt | B32: =B28-B29+B30+B31 -> 6035 | C32: =C28-C29+C30+C31 -> 6051 | D32: =D28-D29+D30+D31 -> 5452 | E32: =E28-E29+E30+E31 -> 5480 | G32: =A32 -> = Résultat avant impôt | H32: =B32/B$15 -> 0.15162936 | I32: =C32/C$15 -> 0.15991015 | J32: =D32/D$15 -> 0.14687896 | K32: =E32/E$15 -> 0.14061738
A33: - Impôt sur les bénéfices | B33: 1678 | C33: 1967 | D33: 1435 | E33: 1283 | G33: =A33 -> - Impôt sur les bénéfices | H33: =B33/B$15 -> 0.042159745 | I33: =C33/C$15 -> 0.05198203 | J33: =D33/D$15 -> 0.038659447 | K33: =E33/E$15 -> 0.032921916
A34: Résultat net de l'ensemble consolidé | B34: =B32-B33 -> 4357 | C34: =C32-C33 -> 4084 | D34: =D32-D33 -> 4017 | E34: =E32-E33 -> 4197 | G34: =A34 -> Résultat net de l'ensemble consolidé | H34: =B34/B$15 -> 0.10946961 | I34: =C34/C$15 -> 0.10792812 | J34: =D34/D$15 -> 0.10821951 | K34: =E34/E$15 -> 0.10769547
A35: - Intérêts minoritaires | D35: 0 | E35: 0 | G35: =A35 -> - Intérêts minoritaires | H35: =B35/B$15 -> 0 | I35: =C35/C$15 -> 0 | J35: =D35/D$15 -> 0 | K35: =E35/E$15 -> 0
A36: = Résultat net part du groupe | B36: =B34-B35 -> 4357 | C36: =C34-C35 -> 4084 | D36: =D34-D35 -> 4017 | E36: =E34-E35 -> 4197 | G36: =A36 -> = Résultat net part du groupe | H36: =B36/B$15 -> 0.10946961 | I36: =C36/C$15 -> 0.10792812 | J36: =D36/D$15 -> 0.10821951 | K36: =E36/E$15 -> 0.10769547
A38: Tableau des flux de trésorerie
A40: =A7 -> En million de FCFA | B40: =B7 -> 2015 | C40: =C7 -> 2016 | D40: =D7 -> 2017 | E40: =E7 -> 2018
A41: Résultat net de l'ensemble consolidé | B41: =B34 -> 4357 | C41: =C34 -> 4084 | D41: =D34 -> 4017 | E41: =E34 -> 4197
A42: + Dotation aux amortissements | B42: =B27 -> 1068 | C42: =C27 -> 1061 | D42: =D27 -> 1168 | E42: =E27 -> 933
A43: + Charges et produits sans incidence sur la trésorerie | B43: 564 | C43: -81 | D43: -47 | E43: 725
A44: = Capacité d’autofinancement | B44: =B41+B42+B43 -> 5989 | C44: =C41+C42+C43 -> 5064 | D44: =D41+D42+D43 -> 5138 | E44: =E41+E42+E43 -> 5855
A45: - Variation du besoin en fonds de roulement d'exploitation | B45: -75 | C45: =C75-B75 -> 6556 | D45: =D75-C75 -> -1426 | E45: =E75-D75 -> -4077
...

Sheet Questions et réponses
A1: CORRIGE QUIZ PREALABLE UNIWAX
B2: Questions/réponses | D2: Réponse | G2: Points | H2: Explication
A4: 1 | B4: Quel est le taux de croissance moyen annuel du chiffre d’affaires de Uniwax entre 2015 et 2018 ? Avec deux chiffres après la virgule. Si vous avez trouvé 15,483 %, tapez 15,48. | D4: =((Anafi!E8/Anafi!B8)^0.333-1)*100 -> -0.35458682 | G4: 2 | H4: (Chiffre d'affaires 2018/ chiffre d'affaires 2015) ^ 0,333-1
A6: =A4+1 -> 2 | B6: Quel est le taux de croissance moyen annuel en volume des ventes de Uniwax entre 2015 et 2018 ? Avec deux chiffres après la virgule. Si vous avez trouvé 15,483 %, tapez 15,48. | D6: =((Anafi!E9/Anafi!B9)^0.333-1)*100 -> -0.81373664 | G6: 2 | H6: (Ventes en volume 2018/ ventes en volume 2015) ^ 0,333-1
A8: =A6+1 -> 3 | B8: Pensez-vous que Uniwax ait fait des acquisitions significatives de nouvelles filiales entre 2015 et 2018 ? | G8: 1 | H8: Non, car sinon on verrait selon toute vraisemblance du goodwill ou du badwill parmi les immobilisations incorporelles du bilan. Il y aurait, par ailleurs, l'année de la première consolidation un bond du chiffre d'affaires du groupe qui intégrerait alors le chiffre d'affaires de la nouvelle filiale acquise.
B9: Oui
B10: Non | D10: X
A12: =A8+1 -> 4 | B12: Pensez-vous que Uniwax ait fait des cessions significatives de filiales entre 2015 et 2018 ? | G12: 1 | H12: Non, car sinon on verrait au compte de résultat une plus ou moins-value exceptionnelle.
B13: Oui
B14: Non | D14: X
A16: =A12+1 -> 5 | B16: Déduisez de vos réponses aux quatre questions précédentes, quel a été le taux de croissance moyen annuel en prix des ventes de Uniwax entre 2015 et 2018 ? Avec deux chiffres après la virgule. Si vous avez trouvé 15,483 %, tapez 15,48. | D16: =((D4/100-D6/100)/(1+D4/100))*100 -> 0.4607837 | G16: 1 | H16: 0
A18: =A16+1 -> 6 | B18: L’activité de Uniwax est-elle ? | G18: 2
B19: Saisonnière | H19: On ne voit pas très bien au nom de quoi elle serait saisonnière ou cyclique pour un bien de consommation courante d'assez faible valeur unitaire qui correspond à un besoin de la vie courante (s'habiller).
B20: Fortement cyclique
B21: Non saisonnière | D21: X
B22: Non cyclique | D22: X
A24: =A18+1 -> 7 | B24: Si vous deviez choisir entre ces 4 pourcentages pour la fraction des achats consommés correspondant à des coûts variables, lequel choisiriez-vous ? | G24: 2 | H24: Les achats consommés varient logiquement avec l'activité, peut-être pas à 100 % totalement, mais probablement beaucoup plus qu'à 50 %.
B25: 0
B26: 0.25
B27: 0.5
B28: 1 | D28: X
A30: =A24+1 -> 8 | B30: Si vous deviez choisir entre ces 4 pourcentages pour la fraction des charges externes correspondant à des coûts variables, lequel choisiriez-vous ? | G30: 2 | H30: Certaines charges externes sont des coûts fixes (comme la rémunération des auditeurs externes), d'autres sont des coûts variables comme les frais de publicité ou de logistique. Dès lors, 0 % et 100 % sont des réponses fausses. 10 % de coûts variables parait moins probable que 50 % puisque la charge externe donnée comme exemple sont les frais de communication qui sont variables.
B31: 0
B32: 0.1
B33: 0.5 | D33: X
B34: 1
A36: =A30+1 -> 9 | B36: Si vous deviez choisir entre ces 4 pourcentages pour la fraction des frais de personnel correspondant à des coûts variables, lequel choisiriez-vous ? | G36: 2 | H36: Quand l'activité d'une usine et de ses magasins baisse, certains postes peuvent être supprimés, les contrats d'intérimaires ne pas être renouvelés, mais surement pas pour 50 ou 100 % des effectifs !
B37: 0
B38: 0.1 | D38: X
B39: 0.5
B40: 1
A42: =A36+1 -> 10 | B42: Si vous deviez choisir entre ces 4 pourcentages pour la fraction des dotations aux amortissements correspondant à des coûts variables, lequel choisiriez-vous ? | G42: 2 | H42: Les dotations aux amortissements sont des coûts fixes qui ne varient que par plages d'activité
B43: 0 | D43: X
B44: 0.1
B45: 0.5
B46: 1
A47: =A42+1 -> 11 | B47: Calculez alors le point mort d'exploitation de Uniwax pour 2018, en reprenant les pourcentages estimés plus hauts et en considérant que le restant des coûts d'exploitation se partage à moitié entre coûts fixes et coûts variables. | D47: =(50%*Anafi!E21+90%*Anafi!E23+100%*Anafi!E27+50%*Anafi!E24-50%*Anafi!E25)/((Anafi!E8-100%*Anafi!E16-50%*Anafi!E21-10%*Anafi!E23-50%*Anafi!E24+50%*Anafi!E25)/Anafi!E8) -> 22294.602 | G47: 1 | H47: Point mort = Couts fixes / taux de marge sur coûts variables en % du CA = ( 50 % des charges externes + 90 % des frais de personnel + 100 % des dotations aux amortissements + 50 % des autres postes) / ( Ventes - 100 % des achats consommés - 50 % des charges externes - 10 % des frais de personnel - 50 % des autres postes)/ventes. Voir le calcul de la case D sur cette ligne.
A49: =A47+1 -> 12 | B49: Que pensez-vous de la position de Uniwax par rapport à son point mort ? | G49: 1 | H49: Être en 2018 à 38977/22295 - 1 = 75 % au dessus de son point mort est une situation très favorable, qui s'explique par l'importance de la marge opérationnelle à plus de 14 %, qui est le niveau des meilleurs groupes européens cotés en bourse d'une taille bien supérieure.
B51: Je suis assez inquiet car Uniwax se rapproche de son point mort.
B52: Uniwax est proche de son point mort, ce qui n'est pas une grande surprise car ses marges d'exploitation sont copieuses.
...

Sheet Annexe 2
B10: En M de FCFA | C10: 2015 | D10: =C10+1 -> 2016 | E10: =D10+1 -> 2017 | F10: =E10+1 -> 2018
B12: Immobilisations corporelles brutes | C12: =3981+405+15226+358 -> 19970 | E12: 27368 | F12: 30164
